<?xml version="1.0"?>
<robot xmlns:xacro="http://www.ros.org/wiki/xacro" >

    <xacro:include filename="inertial_macros.xacro" />

    <material name="white">
        <color rgba="1 1 1 1" />
    </material>

    <material name="orange">
        <color rgba="1 0.3 0.1 1"/>
    </material>

    <material name="blue">
        <color rgba="0.2 0.2 1 1"/>
    </material>

    <material name="black">
        <color rgba="0 0 0 1"/>
    </material>

    <material name="red">
        <color rgba="1 0 0 1"/>
    </material>

    <!-- BASE LINK -->

    <link name="base_link">

    </link>

    <!-- BASE_FOOTPRINT LINK -->

    <joint name="base_footprint_joint" type="fixed">
        <parent link="base_link"/>
        <child link="base_footprint"/>
        <origin xyz="0 0 0" rpy="0 0 0"/>
    </joint>

    <link name="base_footprint">
    </link>

    <joint name="chassis_joint" type="fixed">
        <parent link="base_link"/>
        <child link="chassis"/>
        <origin xyz="0 0 0"/>
    </joint>

    <link name="chassis">
        <visual>
            <origin xyz="0 0 0" rpy="0 0 0"/>
            <geometry>
                <mesh filename="file:///home/tanyong/carty_ws/src/articubot_one/description/Model/model1.dae" scale="1 1 1"/>
            </geometry>
            <material name="white"/>
        </visual>
        <collision>
            <geometry>
                <mesh filename="file:///home/tanyong/carty_ws/src/articubot_one/description/Model/model1.dae" scale="1 1 1"/>
            </geometry>
            <material name="white"/>
        </collision>
        <xacro:inertial_box mass="4" x="0.5" y="0.5" z="0.01">
            <origin xyz="0.253 -0.406 0.05" rpy="0 0 0"/>
        </xacro:inertial_box>
    </link>

    <!-- LEFT WHEEL -->

    <joint name="left_wheel_joint" type="continuous">
        <parent link="base_link"/>
        <child link="left_wheel"/>
        <origin xyz="-0.03 -0.04 0" rpy="-${pi/2} 0 0"/>
        <axis xyz="1 0 0"/>
    </joint>

    <link name="left_wheel">
        <visual>
            <geometry>
                <mesh filename="file:///home/tanyong/carty_ws/src/articubot_one/description/Model/wheel4.dae" scale="1 1 1"/>
            </geometry>
            <material name="blue"/>
        </visual>
        <collision>
            <geometry>
                <mesh filename="file:///home/tanyong/carty_ws/src/articubot_one/description/Model/wheel4.dae" scale="1 1 1"/>
            </geometry>
            <material name="blue"/>
        </collision>
        <xacro:inertial_cylinder mass="0.1" length="0.05" radius="0.05">
            <origin xyz="0 0 0" rpy="0 0 0"/>
        </xacro:inertial_cylinder>
    </link>

    <!-- LEFT WHEEL1 -->

    <joint name="left_wheel1_joint" type="continuous">
        <parent link="base_link"/>
        <child link="left_wheel1"/>
        <origin xyz="0.53 -0.04 0" rpy="-${pi/2} 0 0"/>
        <axis xyz="1 0 0"/>
    </joint>

    <link name="left_wheel1">
        <visual>
            <geometry>
                <mesh filename="file:///home/tanyong/carty_ws/src/articubot_one/description/Model/wheel4.dae" scale="1 1 1"/>
            </geometry>
            <material name="blue"/>
        </visual>
        <collision>
            <geometry>
                <mesh filename="file:///home/tanyong/carty_ws/src/articubot_one/description/Model/wheel4.dae" scale="1 1 1"/>
            </geometry>
            <material name="blue"/>
        </collision>
        <xacro:inertial_cylinder mass="0.1" length="0.05" radius="0.05">
            <origin xyz="0 0 0" rpy="0 0 0"/>
        </xacro:inertial_cylinder>
    </link>

    <!-- RIGHT WHEEL -->

    <joint name="right_wheel_joint" type="continuous">
        <parent link="base_link"/>
        <child link="right_wheel"/>
        <origin xyz="-0.03 -0.7 0" rpy="-${pi/2} 0 0"/>
        <axis xyz="1 0 0"/>
    </joint>

    <link name="right_wheel">
        <visual>
            <geometry>
                <mesh filename="file:///home/tanyong/carty_ws/src/articubot_one/description/Model/wheel4.dae" scale="1 1 1"/>
            </geometry>
            <material name="blue"/>
        </visual>
        <collision>
            <geometry>
                <mesh filename="file:///home/tanyong/carty_ws/src/articubot_one/description/Model/wheel4.dae" scale="1 1 1"/>
            </geometry>
            <material name="blue"/>
        </collision>
        <xacro:inertial_cylinder mass="0.1" length="0.05" radius="0.05">
            <origin xyz="0 0 0" rpy="0 0 0"/>
        </xacro:inertial_cylinder>
    </link>

        <!-- RIGHT WHEEL1 -->

    <joint name="right_wheel1_joint" type="continuous">
        <parent link="base_link"/>
        <child link="right_wheel1"/>
        <origin xyz="0.53 -0.7 0" rpy="-${pi/2} 0 0"/>
        <axis xyz="1 0 0"/>
    </joint>

    <link name="right_wheel1">
        <visual>
            <geometry>
                <mesh filename="file:///home/tanyong/carty_ws/src/articubot_one/description/Model/wheel4.dae" scale="1 1 1"/>
            </geometry>
            <material name="blue"/>
        </visual>
        <collision>
            <geometry>
                <mesh filename="file:///home/tanyong/carty_ws/src/articubot_one/description/Model/wheel4.dae" scale="1 1 1"/>
            </geometry>
            <material name="blue"/>
        </collision>
        <xacro:inertial_cylinder mass="0.1" length="0.05" radius="0.05">
            <origin xyz="0 0 0" rpy="0 0 0"/>
        </xacro:inertial_cylinder>
    </link>

    <joint name="plate_joint" type="prismatic">
        <parent link="base_link"/>
        <child link="plate"/>
        <origin xyz="0.253 -0.406 0.1502"/>
        <axis xyz="0 0 1"/>
        <limit lower="0.0" upper="0.7" effort="-1" velocity="-1"/>

    </joint>

    <link name="plate">
        <visual>
            <origin xyz="0 0 0" rpy="0 0 0"/>
            <geometry>
                <mesh filename="file:///home/tanyong/carty_ws/src/articubot_one/description/Model/plate.dae" scale="1 1 1"/>
            </geometry>
            <material name="white"/>
        </visual>
        <collision>
            <geometry>
                <mesh filename="file:///home/tanyong/carty_ws/src/articubot_one/description/Model/plate.dae" scale="1 1 1"/>
            </geometry>
            <material name="white"/>
        </collision>
        <xacro:inertial_box mass="0.1" x="0.5" y="0.5" z="0.1">
            <origin xyz="0 0 0" rpy="0 0 0"/>
        </xacro:inertial_box>
    </link>


</robot>